<mujoco model="humanoid">
    <compiler angle="degree" inertiafromgeom="true"/>
    <default>
        <joint armature="1" damping="1" limited="true"/>
        <geom conaffinity="1" condim="3" friction="0.8 0.1 0.1" contype="1" margin="0.001" material="geom" rgba="0.8 0.6 .4 1"/>
        <motor ctrllimited="true" ctrlrange="-.4 .4"/>
    </default>
    <option integrator="RK4" iterations="50" solver="PGS" timestep="0.003">
        <!-- <flags solverstat="enable" energy="enable"/>-->
    </option>
    <asset>
        <texture type="skybox" builtin="gradient" width="128" height="128" rgb1=".4 .6 .8" 
            rgb2="0 0 0"/>  
        <texture name="texgeom" type="cube" builtin="flat" mark="cross" width="127" height="1278" 
            rgb1="0.8 0.6 0.4" rgb2="0.8 0.6 0.4" markrgb="1 1 1" random="0.01"/>  
        <texture name="texplane" type="2d" builtin="checker" rgb1=".2 .3 .4" rgb2=".1 0.15 0.2" 
            width="512" height="512"/>  

        <material name='MatPlane' reflectance='0.3' texture="texplane" texrepeat="1 1" texuniform="true"/>
        <material name='geom' texture="texgeom" texuniform="true"/>
    </asset>
    <size nkey="5" nuser_geom="1"/>
    <visual>
        <map fogend="5" fogstart="3"/>
    </visual>
    <worldbody>
        <geom name='floor' pos='0 0 0' size='5 5 .125' type='plane' material="MatPlane" condim='3'/>

        <light mode='targetbodycom' target='torso' directional='false' diffuse='.8 .8 .8' specular='0.3 0.3 0.3' pos='0 0 4.0' dir='0 0 -1'/>

		<camera name='targeting' pos='1 1 2' mode='targetbodycom' target='torso'/>
        <body name="torso" pos="0 0 1.11">
      <joint armature="0" axis="1 0 0" damping="0" limited="false" name="rootx" pos="0 0 0" stiffness="0" type="slide"/>
      <joint armature="0" axis="0 0 1" damping="0" limited="false" name="rootz" pos="0 0 0" ref="1.25" stiffness="0" type="slide"/>
      <joint armature="0" axis="0 1 0" damping="0" limited="false" name="rooty" pos="0 0 1.25" stiffness="0" type="hinge"/>
			<geom contype="0" pos="0 0 0" name="vis_root" size="0.001" type="sphere" rgba=".2 .5 1 1" />
			<body name="lowerback" pos="-0.021 -0.007 0.122">
				<geom fromto="0.0 -0.11 -0.09 0.0 0.11 -0.09" name="lowerback" size="0.09" type="capsule" />
				<geom contype="0" pos="0.021 0.007 -0.122" name="vis_lowerback" size="0.001" type="sphere" rgba=".2 .5 1 1" />
				<joint armature="0.1" damping="4.5" name="lowerback_x" axis="0.0 1.0 0.0" pos="0.021 0.007 -0.122" stiffness="33.83077082487666" type="hinge" range="-20.0 45.0" />
				<joint armature="0.1" damping="4.5" name="lowerback_y" axis="0.0 0.0 1.0" pos="0.021 0.007 -0.122" stiffness="33.83077082487666" type="hinge" range="-30.0 30.0" />
				<joint armature="0.1" damping="4.5" name="lowerback_z" axis="1.0 0.0 0.0" pos="0.021 0.007 -0.122" stiffness="33.83077082487666" type="hinge" range="-30.0 30.0" />
				<body name="upperback" pos="0.01 0.001 0.126">
					<geom fromto="0.0 -0.07 -0.06 0.0 0.07 -0.06" name="upperback" size="0.07" type="capsule" />
					<geom contype="0" pos="-0.01 -0.001 -0.126" name="vis_upperback" size="0.001" type="sphere" rgba=".2 .5 1 1" />
					<joint armature="0.1" damping="4.5" name="upperback_x" axis="0.0 1.0 0.0" pos="-0.01 -0.001 -0.126" stiffness="30.941527168673854" type="hinge" range="-20.0 45.0" />
					<joint armature="0.1" damping="4.5" name="upperback_y" axis="0.0 0.0 1.0" pos="-0.01 -0.001 -0.126" stiffness="30.941527168673854" type="hinge" range="-30.0 30.0" />
					<joint armature="0.1" damping="4.5" name="upperback_z" axis="1.0 0.0 0.0" pos="-0.01 -0.001 -0.126" stiffness="30.941527168673854" type="hinge" range="-30.0 30.0" />
					<body name="thorax" pos="0.02 0.005 0.123">
						<geom fromto="0.0 -0.15 -0.06 0.0 0.15 -0.06" name="thorax" size="0.07" type="capsule" />
						<geom contype="0" pos="-0.02 -0.005 -0.123" name="vis_thorax" size="0.001" type="sphere" rgba=".2 .5 1 1" />
						<joint armature="0.1" damping="4.5" name="thorax_x" axis="0.0 1.0 0.0" pos="-0.02 -0.005 -0.123" stiffness="32.92455687003865" type="hinge" range="-20.0 45.0" />
						<joint armature="0.1" damping="4.5" name="thorax_y" axis="0.0 0.0 1.0" pos="-0.02 -0.005 -0.123" stiffness="32.92455687003865" type="hinge" range="-30.0 30.0" />
						<joint armature="0.1" damping="4.5" name="thorax_z" axis="1.0 0.0 0.0" pos="-0.02 -0.005 -0.123" stiffness="32.92455687003865" type="hinge" range="-30.0 30.0" />
						<body name="lowerneck" pos="0.008 -0.002 0.122">
							<geom fromto="0.0 -0.12 -0.06 0.0 0.12 -0.06" name="lowerneck" size="0.06" type="capsule" />
							<geom contype="0" pos="-0.008 0.002 -0.122" name="vis_lowerneck" size="0.001" type="sphere" rgba=".2 .5 1 1" />
							<joint armature="0.1" damping="0.5" name="lowerneck_x" axis="0.0 1.0 0.0" pos="-0.008 0.002 -0.122" stiffness="35.603801929157775" type="hinge" range="-20.0 45.0" />
							<joint armature="0.1" damping="0.5" name="lowerneck_y" axis="0.0 0.0 1.0" pos="-0.008 0.002 -0.122" stiffness="35.603801929157775" type="hinge" range="-30.0 30.0" />
							<joint armature="0.1" damping="0.5" name="lowerneck_z" axis="1.0 0.0 0.0" pos="-0.008 0.002 -0.122" stiffness="35.603801929157775" type="hinge" range="-30.0 30.0" />
							<body name="upperneck" pos="-0.022 0.004 0.121">
								<geom fromto="0.022 -0.004 -0.121 0 0 0" name="upperneck" size="0.05" type="capsule" />
								<geom contype="0" pos="0.022 -0.004 -0.121" name="vis_upperneck" size="0.001" type="sphere" rgba=".2 .5 1 1" />
								<joint armature="0.1" damping="0.5" name="upperneck_x" axis="0.0 1.0 0.0" pos="0.022 -0.004 -0.121" stiffness="34.95552447049497" type="hinge" range="-20.0 45.0" />
								<joint armature="0.1" damping="0.5" name="upperneck_y" axis="0.0 0.0 1.0" pos="0.022 -0.004 -0.121" stiffness="34.95552447049497" type="hinge" range="-30.0 30.0" />
								<joint armature="0.1" damping="0.5" name="upperneck_z" axis="1.0 0.0 0.0" pos="0.022 -0.004 -0.121" stiffness="34.95552447049497" type="hinge" range="-30.0 30.0" />
								<body name="head" pos="-0.008 0.001 0">
									<geom name="head" size="0.1" type="sphere" />
									<geom contype="0" pos="0.008 -0.001 -0.123" name="vis_head" size="0.001" type="sphere" rgba=".2 .5 1 1" />
									<joint armature="0.1" damping="0.5" name="head_x" axis="0.0 1.0 0.0" pos="0.008 -0.001 -0.123" stiffness="33.68230668604391" type="hinge" range="-20.0 45.0" />
									<joint armature="0.1" damping="0.5" name="head_y" axis="0.0 0.0 1.0" pos="0.008 -0.001 -0.123" stiffness="33.68230668604391" type="hinge" range="-30.0 30.0" />
									<joint armature="0.1" damping="0.5" name="head_z" axis="1.0 0.0 0.0" pos="0.008 -0.001 -0.123" stiffness="33.68230668604391" type="hinge" range="-30.0 30.0" />
								</body>
							</body>
						</body>

						<body name="lclavicle" pos="-0.028 0.243 0.053">
							<geom fromto="0.028 -0.243 -0.053 0 0 0" name="lclavicle" size="0.03" type="capsule" />
							<geom contype="0" pos="0.028 -0.243 -0.053" name="vis_lclavicle" size="0.001" type="sphere" rgba=".2 .5 1 1" />
							<joint armature="0.1" damping="0.5" name="lclavicle_y" axis="0.0 0.0 1.0" pos="0.028 -0.243 -0.053" stiffness="2.012028392586424" type="hinge" range="-20.0 10.0" />
							<joint armature="0.1" damping="0.5" name="lclavicle_z" axis="1.0 0.0 0.0" pos="0.028 -0.243 -0.053" stiffness="2.012028392586424" type="hinge" range="0.0 20.0" />
							<body name="lhumerus" pos="0.0 0.328 -0.0">
								<geom fromto="-0.0 -0.328 0.0 0 0 0" name="lhumerus" size="0.04" type="capsule" />
								<geom contype="0" pos="-0.0 -0.328 0.0" name="vis_lhumerus" size="0.001" type="sphere" rgba=".2 .5 1 1" />
								<joint armature="0.1" damping="0.5" name="lhumerus_x" axis="0.5 0.0 -0.866" pos="-0.0 -0.328 0.0" stiffness="0.6805308084295885" type="hinge" range="-60.0 90.0" />
								<joint armature="0.1" damping="0.5" name="lhumerus_y" axis="0.0 -1.0 0.0" pos="-0.0 -0.328 0.0" stiffness="0.6805308084295885" type="hinge" range="-90.0 90.0" />
								<joint armature="0.1" damping="0.5" name="lhumerus_z" axis="-0.866 -0.0 -0.5" pos="-0.0 -0.328 0.0" stiffness="0.6805308084295885" type="hinge" range="-90.0 90.0" />
								<body name="lradius" pos="0.0 0.177 -0.0">
									<geom fromto="-0.0 -0.177 0.0 0 0 0" name="lradius" size="0.03" type="capsule" />
									<geom contype="0" pos="-0.0 -0.177 0.0" name="vis_lradius" size="0.001" type="sphere" rgba=".2 .5 1 1" />
									<joint armature="0.1" damping="0.5" name="lradius_x" axis="0.5 0.0 -0.866" pos="-0.0 -0.177 0.0" stiffness="8.010694435953429" type="hinge" range="-10.0 170.0" />
									<body name="lwrist" pos="0.0 0.089 -0.0">
										<geom fromto="-0.0 -0.089 0.0 0 0 0" name="lwrist" size="0.03" type="capsule" />
										<geom contype="0" pos="-0.0 -0.089 0.0" name="vis_lwrist" size="0.001" type="sphere" rgba=".2 .5 1 1" />
										<joint armature="0.1" damping="0.5" name="lwrist_y" axis="0.0 -1.0 -0.0" pos="-0.0 -0.089 0.0" stiffness="128.17111097525486" type="hinge" range="-180.0 0.0" />
										<body name="lhand" pos="0.0 0.049 -0.0">
											<geom fromto="-0.0 -0.049 0.0 0 0 0" name="lhand" size="0.03" type="capsule" />
											<geom contype="0" pos="-0.0 -0.049 0.0" name="vis_lhand" size="0.001" type="sphere" rgba=".2 .5 1 1" />
											<joint armature="0.1" damping="0.5" name="lhand_x" axis="-1.0 0.0 0.0" pos="-0.0 -0.049 0.0" stiffness="1382.3505978453854" type="hinge" range="-90.0 90.0" />
											<joint armature="0.1" damping="0.5" name="lhand_z" axis="0.0 -0.0 1.0" pos="-0.0 -0.049 0.0" stiffness="1382.3505978453854" type="hinge" range="-45.0 45.0" />
											<body name="lfingers" pos="0.0 0.039 -0.0">
												<geom fromto="-0.0 -0.039 0.0 0 0 0" name="lfingers" size="0.04" type="capsule" />
												<geom contype="0" pos="-0.0 -0.039 0.0" name="vis_lfingers" size="0.001" type="sphere" rgba=".2 .5 1 1" />
												<joint armature="0.1" damping="0.5" name="lfingers_x" axis="-1.0 0.0 0.0" pos="-0.0 -0.039 0.0" stiffness="3271.848764335726" type="hinge" range="0.0 90.0" />
											</body>
										</body>

										<body name="lthumb" pos="0.04 0.04 -0.0">
											<geom fromto="-0.04 -0.04 0.0 0 0 0" name="lthumb" size="0.02" type="capsule" />
											<geom contype="0" pos="-0.04 -0.04 0.0" name="vis_lthumb" size="0.001" type="sphere" rgba=".2 .5 1 1" />
											<joint armature="0.1" damping="0.5" name="lthumb_x" axis="-0.707 0.707 -0.0" pos="-0.04 -0.04 0.0" stiffness="769.85470621569" type="hinge" range="-45.0 45.0" />
											<joint armature="0.1" damping="0.5" name="lthumb_z" axis="0.0 0.0 1.0" pos="-0.04 -0.04 0.0" stiffness="769.85470621569" type="hinge" range="-45.0 45.0" />
										</body>
									</body>
								</body>
							</body>
						</body>

						<body name="rclavicle" pos="-0.031 -0.256 0.034">
							<geom fromto="0.031 0.256 -0.034 0 0 0" name="rclavicle" size="0.03" type="capsule" />
							<geom contype="0" pos="0.031 0.256 -0.034" name="vis_rclavicle" size="0.001" type="sphere" rgba=".2 .5 1 1" />
							<joint armature="0.1" damping="0.5" name="rclavicle_y" axis="0.0 0.0 1.0" pos="0.031 0.256 -0.034" stiffness="1.729735682259958" type="hinge" range="-10.0 20.0" />
							<joint armature="0.1" damping="0.5" name="rclavicle_z" axis="1.0 0.0 0.0" pos="0.031 0.256 -0.034" stiffness="1.729735682259958" type="hinge" range="-20.0 0.0" />
							<body name="rhumerus" pos="0.0 -0.309 -0.0">
								<geom fromto="-0.0 0.309 0.0 0 0 0" name="rhumerus" size="0.04" type="capsule" />
								<geom contype="0" pos="-0.0 0.309 0.0" name="vis_rhumerus" size="0.001" type="sphere" rgba=".2 .5 1 1" />
								<joint armature="0.1" damping="0.5" name="rhumerus_x" axis="-0.5 0.0 0.866" pos="-0.0 0.309 0.0" stiffness="0.8659070860042668" type="hinge" range="-90.0 60.0" />
								<joint armature="0.1" damping="0.5" name="rhumerus_y" axis="0.0 1.0 0.0" pos="-0.0 0.309 0.0" stiffness="0.8659070860042668" type="hinge" range="-90.0 90.0" />
								<joint armature="0.1" damping="0.5" name="rhumerus_z" axis="-0.866 0.0 -0.5" pos="-0.0 0.309 0.0" stiffness="0.8659070860042668" type="hinge" range="-90.0 90.0" />
								<body name="rradius" pos="-0.0 -0.191 -0.0">
									<geom fromto="0.0 0.191 0.0 0 0 0" name="rradius" size="0.03" type="capsule" />
									<geom contype="0" pos="0.0 0.191 0.0" name="vis_rradius" size="0.001" type="sphere" rgba=".2 .5 1 1" />
									<joint armature="0.1" damping="0.5" name="rradius_x" axis="-0.5 0.0 0.866" pos="0.0 0.191 0.0" stiffness="5.958274283351953" type="hinge" range="-10.0 170.0" />
									<body name="rwrist" pos="0.0 -0.095 -0.0">
										<geom fromto="-0.0 0.095 0.0 0 0 0" name="rwrist" size="0.03" type="capsule" />
										<geom contype="0" pos="-0.0 0.095 0.0" name="vis_rwrist" size="0.001" type="sphere" rgba=".2 .5 1 1" />
										<joint armature="0.1" damping="0.5" name="rwrist_y" axis="0.0 1.0 -0.0" pos="-0.0 0.095 0.0" stiffness="95.33372073349155" type="hinge" range="-180.0 0.0" />
										<body name="rthumb" pos="0.041 -0.041 -0.0">
											<geom fromto="-0.041 0.041 0.0 0 0 0" name="rthumb" size="0.02" type="capsule" />
											<geom contype="0" pos="-0.041 0.041 0.0" name="vis_rthumb" size="0.001" type="sphere" rgba=".2 .5 1 1" />
											<joint armature="0.1" damping="0.5" name="rthumb_x" axis="0.707 0.707 0.0" pos="-0.041 0.041 0.0" stiffness="671.5725370406799" type="hinge" range="-45.0 45.0" />
											<joint armature="0.1" damping="0.5" name="rthumb_z" axis="0.0 -0.0 1.0" pos="-0.041 0.041 0.0" stiffness="671.5725370406799" type="hinge" range="-45.0 45.0" />
										</body>

										<body name="rhand" pos="0.0 -0.051 -0.0">
											<geom fromto="-0.0 0.051 0.0 0 0 0" name="rhand" size="0.03" type="capsule" />
											<geom contype="0" pos="-0.0 0.051 0.0" name="vis_rhand" size="0.001" type="sphere" rgba=".2 .5 1 1" />
											<joint armature="0.1" damping="0.5" name="rhand_x" axis="1.0 0.0 0.0" pos="-0.0 0.051 0.0" stiffness="1205.8719094761386" type="hinge" range="-90.0 90.0" />
											<joint armature="0.1" damping="0.5" name="rhand_z" axis="0.0 0.0 1.0" pos="-0.0 0.051 0.0" stiffness="1205.8719094761386" type="hinge" range="-45.0 45.0" />
											<body name="rfingers" pos="0.0 -0.041 -0.0">
												<geom fromto="-0.0 0.041 0.0 0 0 0" name="rfingers" size="0.04" type="capsule" />
												<geom contype="0" pos="-0.0 0.041 0.0" name="vis_rfingers" size="0.001" type="sphere" rgba=".2 .5 1 1" />
												<joint armature="0.1" damping="0.5" name="rfingers_x" axis="1.0 0.0 0.0" pos="-0.0 0.041 0.0" stiffness="2854.1346326179755" type="hinge" range="0.0 90.0" />
											</body>
										</body>
									</body>
								</body>
							</body>
						</body>
					</body>
				</body>
			</body>

			<body name="rhipjoint" pos="0.074 -0.124 -0.106">
				<geom fromto="-0.074 0.124 0.106 0 0 0" name="rhipjoint" size="0.08" type="capsule" />
				<geom contype="0" pos="-0.074 0.124 0.106" name="vis_rhipjoint" size="0.001" type="sphere" rgba=".2 .5 1 1" />
				<body name="rfemur" pos="0.0 -0.14 -0.383">
					<geom fromto="-0.0 0.14 0.383 0 0 0" name="rfemur" size="0.076" type="capsule" />
					<geom contype="0" pos="-0.0 0.14 0.383" name="vis_rfemur" size="0.001" type="sphere" rgba=".2 .5 1 1" />
					<joint armature="0.1" damping="0.5" name="rfemur_x" axis="0.0 0.94 -0.342" pos="-0.0 0.14 0.383" stiffness="0.28507598521808314" type="hinge" range="-160.0 20.0" />
					<joint armature="0.1" damping="0.5" name="rfemur_y" axis="0.0 0.342 0.94" pos="-0.0 0.14 0.383" stiffness="0.28507598521808314" type="hinge" range="-70.0 70.0" />
					<joint armature="0.1" damping="0.5" name="rfemur_z" axis="1.0 0.0 0.0" pos="-0.0 0.14 0.383" stiffness="0.28507598521808314" type="hinge" range="-70.0 60.0" />
					<body name="rtibia" pos="0.0 -0.177 -0.486">
						<geom fromto="-0.0 0.177 0.486 0 0 0" name="rtibia" size="0.06" type="capsule" />
						<geom contype="0" pos="-0.0 0.177 0.486" name="vis_rtibia" size="0.001" type="sphere" rgba=".2 .5 1 1" />
						<joint armature="0.1" damping="0.5" name="rtibia_x" axis="0.0 0.94 -0.342" pos="-0.0 0.177 0.486" stiffness="0.1103630134642327" type="hinge" range="-10.0 170.0" />
						<body name="rfoot" pos="0.13 -0.006 -0.016">
							<geom fromto="-0.13 0.006 0.016 0 0 0" name="rfoot" size="0.05" type="capsule" />
							<geom contype="0" pos="-0.13 0.006 0.016" name="vis_rfoot" size="0.001" type="sphere" rgba=".2 .5 1 1" />
							<joint armature="0.1" damping="0.5" name="rfoot_x" axis="0.0 0.94 -0.342" pos="-0.13 0.006 0.016" stiffness="26.417703993271576" type="hinge" range="-45.0 90.0" />
							<joint armature="0.1" damping="0.5" name="rfoot_z" axis="0.0 0.342 0.94" pos="-0.13 0.006 0.016" stiffness="26.417703993271576" type="hinge" range="-20.0 70.0" />
							<body name="rtoes" pos="0.067 -0.0 -0.0">
								<geom fromto="-0.067 0.0 0.0 0 0 0" name="rtoes" size="0.05" type="capsule" />
								<geom contype="0" pos="-0.067 0.0 0.0" name="vis_rtoes" size="0.001" type="sphere" rgba=".2 .5 1 1" />
								<joint armature="0.1" damping="0.5" name="rtoes_x" axis="0.0 0.94 -0.342" pos="-0.067 0.0 0.0" stiffness="401.1621055524974" type="hinge" range="-90.0 20.0" />
							</body>
						</body>
					</body>
				</body>
			</body>

			<body name="lhipjoint" pos="0.074 0.14 -0.106">
				<geom fromto="-0.074 -0.14 0.106 0 0 0" name="lhipjoint" size="0.08" type="capsule" />
				<geom contype="0" pos="-0.074 -0.14 0.106" name="vis_lhipjoint" size="0.001" type="sphere" rgba=".2 .5 1 1" />
				<body name="lfemur" pos="0.0 0.136 -0.373">
					<geom fromto="-0.0 -0.136 0.373 0 0 0" name="lfemur" size="0.076" type="capsule" />
					<geom contype="0" pos="-0.0 -0.136 0.373" name="vis_lfemur" size="0.001" type="sphere" rgba=".2 .5 1 1" />
					<joint armature="0.1" damping="0.5" name="lfemur_x" axis="0.0 0.94 0.342" pos="-0.0 -0.136 0.373" stiffness="0.3183275825245205" type="hinge" range="-160.0 20.0" />
					<joint armature="0.1" damping="0.5" name="lfemur_y" axis="0.0 -0.342 0.94" pos="-0.0 -0.136 0.373" stiffness="0.3183275825245205" type="hinge" range="-70.0 70.0" />
					<joint armature="0.1" damping="0.5" name="lfemur_z" axis="1.0 0.0 0.0" pos="-0.0 -0.136 0.373" stiffness="0.3183275825245205" type="hinge" range="-60.0 70.0" />
					<body name="ltibia" pos="0.0 0.183 -0.503">
						<geom fromto="-0.0 -0.183 0.503 0 0 0" name="ltibia" size="0.06" type="capsule" />
						<geom contype="0" pos="-0.0 -0.183 0.503" name="vis_ltibia" size="0.001" type="sphere" rgba=".2 .5 1 1" />
						<joint armature="0.1" damping="0.5" name="ltibia_x" axis="0.0 0.94 0.342" pos="-0.0 -0.183 0.503" stiffness="0.09660960686915877" type="hinge" range="-10.0 170.0" />
						<body name="lfoot" pos="0.133 0.006 -0.017">
							<geom fromto="-0.133 -0.006 0.017 0 0 0" name="lfoot" size="0.05" type="capsule" />
							<geom contype="0" pos="-0.133 -0.006 0.017" name="vis_lfoot" size="0.001" type="sphere" rgba=".2 .5 1 1" />
							<joint armature="0.1" damping="0.5" name="lfoot_x" axis="-0.0 0.94 0.342" pos="-0.133 -0.006 0.017" stiffness="24.5506176838375" type="hinge" range="-45.0 90.0" />
							<joint armature="0.1" damping="0.5" name="lfoot_z" axis="0.0 -0.342 0.94" pos="-0.133 -0.006 0.017" stiffness="24.5506176838375" type="hinge" range="-70.0 20.0" />
							<body name="ltoes" pos="0.068 0.0 -0.0">
								<geom fromto="-0.068 -0.0 0.0 0 0 0" name="ltoes" size="0.05" type="capsule" />
								<geom contype="0" pos="-0.068 -0.0 0.0" name="vis_ltoes" size="0.001" type="sphere" rgba=".2 .5 1 1" />
								<joint armature="0.1" damping="0.5" name="ltoes_x" axis="-0.0 0.94 0.342" pos="-0.068 -0.0 0.0" stiffness="373.7708034312325" type="hinge" range="-90.0 20.0" />
							</body>
						</body>
					</body>
				</body>
			</body>
		</body>
	</worldbody>
    <tendon>
    </tendon>
    <actuator><!-- this section is not supported, same constants in code -->
		<motor gear="20" ctrlrange="-1.0 1.0" joint="lowerback_x" name="lowerback_x"/>
		<motor gear="20" ctrlrange="-1.0 1.0" joint="lowerback_y" name="lowerback_y"/>
		<motor gear="20" ctrlrange="-1.0 1.0" joint="lowerback_z" name="lowerback_z"/>
		<motor gear="20" ctrlrange="-1.0 1.0" joint="lowerneck_x" name="lowerneck_x"/>
		<motor gear="20" ctrlrange="-1.0 1.0" joint="lowerneck_y" name="lowerneck_y"/>
		<motor gear="20" ctrlrange="-1.0 1.0" joint="lowerneck_z" name="lowerneck_z"/>
		<motor gear="40" ctrlrange="-1.0 1.0" joint="rfoot_x" name="rfoot_x"/>
		<motor gear="0" ctrlrange="-1.0 1.0" joint="rfoot_z" name="rfoot_z"/>
		<!--<motor gear="100" ctrlrange="-1.0 1.0" joint="lwrist_y" name="lwrist_y"/>-->
		<!--<motor gear="100" ctrlrange="-1.0 1.0" joint="lhumerus_x" name="lhumerus_x"/>-->
		<!--<motor gear="100" ctrlrange="-1.0 1.0" joint="lhumerus_y" name="lhumerus_y"/>-->
		<!--<motor gear="100" ctrlrange="-1.0 1.0" joint="lhumerus_z" name="lhumerus_z"/>-->
		<!--<motor gear="100" ctrlrange="-1.0 1.0" joint="rclavicle_y" name="rclavicle_y"/>-->
		<!--<motor gear="100" ctrlrange="-1.0 1.0" joint="rclavicle_z" name="rclavicle_z"/>-->
		<motor gear="40" ctrlrange="-1.0 1.0" joint="lfoot_x" name="lfoot_x"/>
		<motor gear="0" ctrlrange="-1.0 1.0" joint="lfoot_z" name="lfoot_z"/>
		<!--<motor gear="100" ctrlrange="-1.0 1.0" joint="lhand_x" name="lhand_x"/>-->
		<!--<motor gear="100" ctrlrange="-1.0 1.0" joint="lhand_z" name="lhand_z"/>-->
		<!--<motor gear="100" ctrlrange="-1.0 1.0" joint="lfingers_x" name="lfingers_x"/>-->
		<motor gear="60" ctrlrange="-1.0 1.0" joint="rtibia_x" name="rtibia_x"/>
		<motor gear="60" ctrlrange="-1.0 1.0" joint="ltibia_x" name="ltibia_x"/>
		<!--<motor gear="100" ctrlrange="-1.0 1.0" joint="rfingers_x" name="rfingers_x"/>-->
		<motor gear="20" ctrlrange="-1.0 1.0" joint="upperback_x" name="upperback_x"/>
		<motor gear="20" ctrlrange="-1.0 1.0" joint="upperback_y" name="upperback_y"/>
		<motor gear="20" ctrlrange="-1.0 1.0" joint="upperback_z" name="upperback_z"/>
		<!--<motor gear="100" ctrlrange="-1.0 1.0" joint="rradius_x" name="rradius_x"/>-->
		<!--<motor gear="100" ctrlrange="-1.0 1.0" joint="rwrist_y" name="rwrist_y"/>-->
		<!--<motor gear="100" ctrlrange="-1.0 1.0" joint="lthumb_x" name="lthumb_x"/>-->
		<!--<motor gear="100" ctrlrange="-1.0 1.0" joint="lthumb_z" name="lthumb_z"/>-->
		<motor gear="60" ctrlrange="-1.0 1.0" joint="rfemur_x" name="rfemur_x"/>
		<motor gear="60" ctrlrange="-1.0 1.0" joint="rfemur_y" name="rfemur_y"/>
		<motor gear="60" ctrlrange="-1.0 1.0" joint="rfemur_z" name="rfemur_z"/>
		<motor gear="20" ctrlrange="-1.0 1.0" joint="thorax_x" name="thorax_x"/>
		<motor gear="20" ctrlrange="-1.0 1.0" joint="thorax_y" name="thorax_y"/>
		<motor gear="20" ctrlrange="-1.0 1.0" joint="thorax_z" name="thorax_z"/>
		<!--<motor gear="100" ctrlrange="-1.0 1.0" joint="rhumerus_x" name="rhumerus_x"/>-->
		<!--<motor gear="100" ctrlrange="-1.0 1.0" joint="rhumerus_y" name="rhumerus_y"/>-->
		<!--<motor gear="100" ctrlrange="-1.0 1.0" joint="rhumerus_z" name="rhumerus_z"/>-->
		<motor gear="20" ctrlrange="-1.0 1.0" joint="upperneck_x" name="upperneck_x"/>
		<motor gear="20" ctrlrange="-1.0 1.0" joint="upperneck_y" name="upperneck_y"/>
		<motor gear="20" ctrlrange="-1.0 1.0" joint="upperneck_z" name="upperneck_z"/>
		<!--<motor gear="100" ctrlrange="-1.0 1.0" joint="rhand_x" name="rhand_x"/>-->
		<!--<motor gear="100" ctrlrange="-1.0 1.0" joint="rhand_z" name="rhand_z"/>-->
		<!--<motor gear="100" ctrlrange="-1.0 1.0" joint="lclavicle_y" name="lclavicle_y"/>-->
		<!--<motor gear="100" ctrlrange="-1.0 1.0" joint="lclavicle_z" name="lclavicle_z"/>-->
		<!--<motor gear="100" ctrlrange="-1.0 1.0" joint="head_x" name="head_x"/>-->
		<!--<motor gear="100" ctrlrange="-1.0 1.0" joint="head_y" name="head_y"/>-->
		<!--<motor gear="100" ctrlrange="-1.0 1.0" joint="head_z" name="head_z"/>-->
		<motor gear="40" ctrlrange="-1.0 1.0" joint="rtoes_x" name="rtoes_x"/>
		<!--<motor gear="100" ctrlrange="-1.0 1.0" joint="lradius_x" name="lradius_x"/>-->
		<motor gear="40" ctrlrange="-1.0 1.0" joint="ltoes_x" name="ltoes_x"/>
		<motor gear="60" ctrlrange="-1.0 1.0" joint="lfemur_x" name="lfemur_x"/>
		<motor gear="60" ctrlrange="-1.0 1.0" joint="lfemur_y" name="lfemur_y"/>
		<motor gear="60" ctrlrange="-1.0 1.0" joint="lfemur_z" name="lfemur_z"/>
		<!--<motor gear="100" ctrlrange="-1.0 1.0" joint="rthumb_x" name="rthumb_x"/>-->
		<!--<motor gear="100" ctrlrange="-1.0 1.0" joint="rthumb_z" name="rthumb_z"/>-->
    </actuator>
</mujoco>
